## 前端异常
### Error对象
- 可以通过构造函数来创建一个新的通用错误
```
const err = new Error("Error");
const err = Error("Error");
throw err; // Uncaught Error: Error
```
- Error对象有三个属性。
  1. message：带有错误消息的字符串。
  2. name: 错误的类型。
  3. stack：函数执行的堆栈跟踪。
- 创建一个TypeError对象，该消息将携带实际的错误字符串，其name将是"TypeError"。
```
const wrongError = TypeError("Expected number");
console.log(wrongError.message); // Expected number
console.log(wrongError.name);    // TypeError
```
### 使用instanceof区分异常类型
```
try {
  // ...
} catch (err) {
  if (err instanceof TypeError) {
    // 处理 TypeError 错误
  } else if (err instanceof RangeError) {
    // 处理 RangeError 错误
  } else {
    // 处理其他类型错误
  }
}
```
### SyntaxError 语法异常
- 在引擎执行代码之前，编译器需要对js进行编译，编译阶段包括：词法分析，语法分析。
- 编译阶段发生的异常都是SyntaxError。
- 绝大部分SyntaxError都可以通过配置编辑器的校验工具在开发阶段避免。
```
// 缺少一个引号  Uncaught SyntaxError: Invalid or unexpected token
const a = "3;
```
### TypeError 类型异常
- TypeError在对值进行不合理操作时会发生，比如试图对一个非函数类型的值进行函数调用，或者引用null或undefined类型的值中的属性，那么引擎会抛出这种类型的异常。
```
// 变量name不能当作函数调用  Uncaught TypeError: name is not a function
const name = 'dyx';
name();
```
### ReferenceError 引用异常
- 当找不到所需的变量时会报ReferenceError引用异常。
```
// a未定义 Uncaught ReferenceError: a is not defined
console.log(a);
```
### RangeError 范围错误
- 错误的数组范围。
```
// 错误的数组长度  Uncaught RangeError: Invalid array length
new Array(-20)
```
- 递归等消耗内存会导致范围错误的异常。Uncaught RangeError: Maximum call stack size exceeded
- 将错误的值传递给数字方法，例如toFixed()等。
```
// Uncaught RangeError: toFixed() digits argument must be between 0 and 100
2.2222.toFixed(111);
```
### URIError
- 使用全局URI处理函数而产生的错误。
- decodeURI, decodeURIComponent, encodeURI, encodeURIComponent这四个方法会产生这种异常。
```
//  Uncaught URIError: URI malformed
decodeURI('%%')
```
### EvalError
- 在eval()方法执行过程中抛出EvalError异常。
- 根据ECMA2018版以后，此异常不再会被抛出，但是EvalError对象仍然保持兼容性。
### InternalError 内部异常
- 这种异常极为少见，在JS引擎内部发生，示例场景通常为某些成分过大。
```
// 过多 case 子句
Uncaught RangeError: too many switch cases
// 正则表达式中括号过多
Uncaught RangeError: too many parentheses in regular expression
// 数组初始化器过大 
Uncaught RangeError: array initializer too large
```
### Script Error
#### 产生原因
- 跨域资源引用，当a域下页面引用了b域下的js文件，运行b域下的js文件中的方法时报了一个异常，此时前端的错误捕获脚本只能检测到一个script error的异常。
- 这是由于浏览器基于安全考虑故意隐藏了其它域JS文件抛出的具体错误信息。这样可以有效避免敏感信息无意中被第三方(不受控制的)脚本捕获到，因此浏览器只允许同域下的脚本捕获具体的错误信息。
#### 解决办法
1. 给script标签增加crossorigin属性，让浏览器允许页面请求资源。
```
// 以下两种写法均可
<scrpit src="..." crossorigin></script>
<scrpit src="..." crossorigin="anonymous"></script> 
```
2. 给静态资源响应头增加允许跨域标记，让服务器允许资源返回。
    - 服务器的HTTP响应头增加Access-Control-Allow-Origin: * 或者 Access-Control-Allow-Origin: ...
    - 大部分主流CDN默认添加了Access-Control-Allow-Origin属性。
#### 已添加crossorigin依然有script error
- 由于部分浏览器对crossorigin属性不支持，或者无法往HTTP响应头里面添加跨域属性，因此依然可能产生script error。
- 可以通过try catch获取页面报错信息，将JS错误重新抛出或者上报。
```
try {
  run(); // 调用b域下的js文件中的方法
} catch (e) {
  console.log(e);
  throw e; 
}
```
### 创建自定义错误类型
```
class MyError extends Error {
  constructor(message) {
    super();
    this.name = "MyError";
    this.message = message;     
  }
}

throw new MyError("自定义错误"); // Uncaught MyError: 自定义错误
```
### 抛出错误
- 错误和异常不同。Error对象(错误)只有在被抛出时才会成为异常。
- 在JavaScript中抛出异常，可以使用throw来抛出Error对象。
```
throw TypeError("Expected number"); // Uncaught TypeError: Expected number
throw new TypeError("Expected number"); // Uncaught TypeError: Expected number
```
- 异常一旦抛出，就会在程序堆栈中冒泡，除非在某个地方被捕获。