## 错误数据采集
### js错误使用window.onerror捕获
- window.onerror可以捕获常规运行时的错误。
- window.onerror可以捕获异步错误(setTimeout)。
- window.onerror无法捕获资源错误和promise的错误。
```
window.onerror = (message, source, lineno, colno, error) => {
  // 上报错误
  lazyReportCache({
    type: 'error',
    subType: 'js',
    time: dayjs().format('YYYY-MM-DD HH:mm:ss'),
    page: location.href,
    data: JSON.stringify({
      message,
      source,
      lineno,
      colno,
      // 错误栈
      errorStack: error.stack
    })
  });
}
```
### 资源加载错误使用window.addEventListener('error', () => {})捕获
- js的错误也能被window.addEventListener('error', () => {})捕获到，判断触发错误的事件对象当只有资源加载错误时才处理。
- 当一项资源(图片或脚本)加载失败，加载资源的元素会触发一个Event接口的error事件，error事件不会向上冒泡到window，window.onerror不能捕获到，可以通过window.addEventListener('error', () => {})捕获资源加载错误。
- window.addEventListener('error', () => {})不能捕获new Image的错误，new Image的错误可以单独处理。
- window.addEventListener('error', () => {})不能捕获promise的错误。
```
window.addEventListener('error', e => {
  const target = e.target;
  if (!target) return;
  // 判断是否为资源加载错误
  if (target.src || target.href) {
    const url = target.src || target.href;
    lazyReportCache({
      type: 'error',
      subType: 'resource',
      time: dayjs().format('YYYY-MM-DD HH:mm:ss'),
      page: location.href,
      data: JSON.stringify({
        message: `${url} 资源加载失败`,
        url,
        html: target.outerHTML,
        resourceType: target.tagName
      })
    });
  }
}, true);
```
### promise错误使用window.addEventListener('unhandledrejection', () => {})捕获
```
window.addEventListener('unhandledrejection', e => {
  lazyReportCache({
    type: 'error',
    subType: 'promise',
    time: dayjs().format('YYYY-MM-DD HH:mm:ss'),
    page: location.href,
    data: JSON.stringify({
      message: e.reason?.message,
      // 错误栈
      errorStack: e.reason?.stack
    })
  });
})
```
### React错误
- react render函数的错误不能被window.onerror捕获到，生命周期函数中的错误可以被window.onerror捕获到，可以通过componentDidCatch声明一个错误边界组件，在错误边界组件中上报错误。
- ErrorBoundary只捕捉发生在React生命周期中的错误，不会捕捉React事件处理、异步代码、ErrorBoundary自己抛出的错误。
- [react的错误开发环境会触发两次，生产环境正常触发一次。](https://github.com/facebook/react/issues/11499)
- [antd的Form的onFinish方法中的错误无法被捕获到](https://github.com/ant-design/ant-design/issues/33876)。
```
class ErrorBoundary extends React.Component {
  constructor(props) {
    super(props);
    this.state = { hasError: false };
  }

  static getDerivedStateFromError(error) {
    // 更新state使下一次渲染能够显示降级后的UI
    return { hasError: true };
  }

  componentDidCatch(error) {
    lazyReportCache({
      type: 'error',
      subType: 'react',
      time: dayjs().format('YYYY-MM-DD HH:mm:ss'),
      page: location.href,
      data: JSON.stringify({
        message: error?.message,
        errorStack: error?.stack
      })
    });
  }

  render() {
    if (this.state.hasError) {
      // 自定义的降级UI
      return <h1>Something went wrong.</h1>;
    }
    return this.props.children; 
  }
}

// 使用ErrorBoundary包裹根组件<App />
const root = ReactDOM.createRoot(document.getElementById('root') as Element);
root.render(<ErrorBoundary><App /></ErrorBoundary>);
```
### Vue错误
- 由于Vue会捕获所有Vue单文件组件或者Vue.extend继承的代码，所以在Vue里面出现的错误，并不会直接被window.onerror捕获，而是会抛给Vue.config.errorHandler。
- 可以在Vue.config.errorHandler中将捕获到的错误直接throw给onerror处理。
```
Vue.config.errorHandler = (err) => {
  setTimeout(() => {
    throw err
  })
}
```
